2023-03-04 15:37:07,762 ERROR 3 columns passed, passed data had 4 columns
Traceback (most recent call last):
  File "C:\Users\kevin\AppData\Local\Programs\Python\Python311\Lib\site-packages\pandas\core\internals\construction.py", line 969, in _finalize_columns_and_data
    columns = _validate_or_indexify_columns(contents, columns)
              ^^^^^^^^^^^^^^^^^^^^^^^^^^^^^^^^^^^^^^^^^^^^^^^^
  File "C:\Users\kevin\AppData\Local\Programs\Python\Python311\Lib\site-packages\pandas\core\internals\construction.py", line 1017, in _validate_or_indexify_columns
    raise AssertionError(
AssertionError: 3 columns passed, passed data had 4 columns

The above exception was the direct cause of the following exception:

Traceback (most recent call last):
  File "C:\Users\kevin\PycharmProjects\Super_Mario_Bros_The_Movie_The_Game\code\main.py", line 84, in <module>
    game = Game()
           ^^^^^^
  File "C:\Users\kevin\PycharmProjects\Super_Mario_Bros_The_Movie_The_Game\code\main.py", line 20, in __init__
    self.settings = Settings()
                    ^^^^^^^^^^
  File "C:\Users\kevin\PycharmProjects\Super_Mario_Bros_The_Movie_The_Game\code\settings.py", line 15, in __init__
    self.get_settings()
  File "C:\Users\kevin\PycharmProjects\Super_Mario_Bros_The_Movie_The_Game\code\settings.py", line 34, in get_settings
    settings_df = pd.DataFrame(cursor.fetchall(), columns=['screen_mode', 'music_vol', 'sfx_vol'])
                  ^^^^^^^^^^^^^^^^^^^^^^^^^^^^^^^^^^^^^^^^^^^^^^^^^^^^^^^^^^^^^^^^^^^^^^^^^^^^^^^^
  File "C:\Users\kevin\AppData\Local\Programs\Python\Python311\Lib\site-packages\pandas\core\frame.py", line 746, in __init__
    arrays, columns, index = nested_data_to_arrays(
                             ^^^^^^^^^^^^^^^^^^^^^^
  File "C:\Users\kevin\AppData\Local\Programs\Python\Python311\Lib\site-packages\pandas\core\internals\construction.py", line 510, in nested_data_to_arrays
    arrays, columns = to_arrays(data, columns, dtype=dtype)
                      ^^^^^^^^^^^^^^^^^^^^^^^^^^^^^^^^^^^^^
  File "C:\Users\kevin\AppData\Local\Programs\Python\Python311\Lib\site-packages\pandas\core\internals\construction.py", line 875, in to_arrays
    content, columns = _finalize_columns_and_data(arr, columns, dtype)
                       ^^^^^^^^^^^^^^^^^^^^^^^^^^^^^^^^^^^^^^^^^^^^^^^
  File "C:\Users\kevin\AppData\Local\Programs\Python\Python311\Lib\site-packages\pandas\core\internals\construction.py", line 972, in _finalize_columns_and_data
    raise ValueError(err) from err
ValueError: 3 columns passed, passed data had 4 columns
